<?xml version="1.0" ?>
<robot name="Bigbot" xmlns:xacro="http://www.ros.org/wiki/xacro">

<link name="base_link"/>

	<link name="bigbot_Base">
		<visual>
			<origin rpy="0 0 0" xyz="0.00000 0.00000 0.00000" />
			<geometry>
				<mesh filename="package://bigbot_description/models/bigbot/meshes/bigbot_frame.dae" scale="0.001 0.001 0.001" />
			</geometry>
		</visual>
		<inertial>
			<origin xyz="0.00002 -0.00003 0.00301" />
			<mass value="116.8" />
			<inertia ixx="4.180745" ixy="30071E-6" ixz="-28790E-6" iyy="8.041496" iyz="34044E-6" izz="9.589644" />
			
    
		</inertial>
	</link>
	<joint name="base_link_to_bigbot_Base" type="fixed">
		<parent link="base_link" />
		<child link="bigbot_Base" />
		<origin rpy="0.0 0.0 0.0" xyz="0.00000 0.00000 0.00000" />
	</joint>
	<link name="bigbot_UCSLF">
		<inertial>
			<mass value="2e-06" />
			<inertia ixx="1.1e-09" ixy="0" ixz="0" iyy="1.1e-09" iyz="0" izz="1.1e-09" />
		</inertial>
	</link>
	<joint name="bigbot_Base_to_bigbot_UCSLF" type="fixed">
		<parent link="bigbot_Base" />
		<child link="bigbot_UCSLF" />
		<origin rpy="-1.5707963267948966 0.0 0.0" xyz="0.27753 0.16887 0.17107" />
	</joint>
	<joint name="bigbot_UCSLF_to_wheel_urdf_3_UCS1" type="continuous">
		<parent link="bigbot_UCSLF" />
		<child link="wheel_urdf_3_UCS1" />
		<origin rpy="0.0 0.0 0.0" xyz="0.00000 0.00000 0.00000" />
		<axis xyz="0 0 1" />
	</joint>
	<link name="wheel_urdf_3_UCS1">
		<inertial>
			<mass value="2e-06" />
			<inertia ixx="1.1e-09" ixy="0" ixz="0" iyy="1.1e-09" iyz="0" izz="1.1e-09" />
		</inertial>
	</link>
	<link name="wheel_urdf_3_Base">
		<visual>
			<origin rpy="0 0 0" xyz="0.00000 0.00000 0.00000" />
			<geometry>
				<mesh filename="package://bigbot_description/models/bigbot/meshes/wheel.dae" scale="0.001 0.001 0.001" />
			</geometry>
		</visual>
		<inertial>
		<origin xyz="0.00016 -0.00000 0.00000" />
			<mass value="2.63" /><!-- x is rotation axis -->
			<inertia ixx="24140e-6" ixy="0" ixz="0" iyy="15166e-6" iyz="0" izz="15166e-6" />
		</inertial>
	</link>
	<joint name="wheel_urdf_3_UCS1_to_wheel_urdf_3_Base" type="fixed">
		<parent link="wheel_urdf_3_UCS1" />
		<child link="wheel_urdf_3_Base" />
		<origin rpy="-0.0 1.5707963057214722 0.0" xyz="-0.00048 0.00039 0.07671" />
	</joint>
	<link name="bigbot_UCSRF">
		<inertial>
			<mass value="2e-06" />
			<inertia ixx="1.1e-09" ixy="0" ixz="0" iyy="1.1e-09" iyz="0" izz="1.1e-09" />
		</inertial>
	</link>
	<joint name="bigbot_Base_to_bigbot_UCSRF" type="fixed">
		<parent link="bigbot_Base" />
		<child link="bigbot_UCSRF" />
		<origin rpy="1.5707963267948966 0.0 0.0" xyz="0.27753 -0.16887 0.17107" />
	</joint>
	<joint name="bigbot_UCSRF_to_wheel_urdf_1_UCS1" type="continuous">
		<parent link="bigbot_UCSRF" />
		<child link="wheel_urdf_1_UCS1" />
		<origin rpy="0.0 0.0 0.0" xyz="0.00000 0.00000 0.00000" />
		<axis xyz="0 0 1" />
	</joint>
	<link name="wheel_urdf_1_UCS1">
		<inertial>
			<mass value="2e-06" />
			<inertia ixx="1.1e-09" ixy="0" ixz="0" iyy="1.1e-09" iyz="0" izz="1.1e-09" />
		</inertial>
	</link>
	<link name="wheel_urdf_1_Base">
		<visual>
			<origin rpy="0 0 0" xyz="0.00000 0.00000 0.00000" />
			<geometry>
				<mesh filename="package://bigbot_description/models/bigbot/meshes/wheel.dae" scale="0.001 0.001 0.001" />
			</geometry>
		</visual>
		<inertial>
			<origin xyz="0.00016 -0.00000 0.00000" />
			<mass value="2.63" /><!-- x is rotation axis -->
			<inertia ixx="24140e-6" ixy="0" ixz="0" iyy="15166e-6" iyz="0" izz="15166e-6" />
		</inertial>
	</link>
	<joint name="wheel_urdf_1_UCS1_to_wheel_urdf_1_Base" type="fixed">
		<parent link="wheel_urdf_1_UCS1" />
		<child link="wheel_urdf_1_Base" />
		<origin rpy="-0.0 1.5707963057214722 0.0" xyz="-0.00048 0.00039 0.07671" />
	</joint>
	<link name="bigbot_UCSLR">
		<inertial>
			<mass value="2e-06" />
			<inertia ixx="1.1e-09" ixy="0" ixz="0" iyy="1.1e-09" iyz="0" izz="1.1e-09" />
		</inertial>
	</link>
	<joint name="bigbot_Base_to_bigbot_UCSLR" type="fixed">
		<parent link="bigbot_Base" />
		<child link="bigbot_UCSLR" />
		<origin rpy="-1.5707963267948966 0.0 0.0" xyz="-0.27753 0.16887 0.17107" />
	</joint>
	<joint name="bigbot_UCSLR_to_wheel_urdf_4_UCS1" type="continuous">
		<parent link="bigbot_UCSLR" />
		<child link="wheel_urdf_4_UCS1" />
		<origin rpy="0.0 0.0 0.0" xyz="0.00000 0.00000 0.00000" />
		<axis xyz="0 0 1" />
	</joint>
	<link name="wheel_urdf_4_UCS1">
		<inertial>
			<mass value="2e-06" />
			<inertia ixx="1.1e-09" ixy="0" ixz="0" iyy="1.1e-09" iyz="0" izz="1.1e-09" />
		</inertial>
	</link>
	<link name="wheel_urdf_4_Base">
		<visual>
			<origin rpy="0 0 0" xyz="0.00000 0.00000 0.00000" />
			<geometry>
				<mesh filename="package://bigbot_description/models/bigbot/meshes/wheel.dae" scale="0.001 0.001 0.001" />
			</geometry>
		</visual>
		<inertial>
			<origin xyz="0.00016 -0.00000 0.00000" />
			<mass value="2.63" /><!-- x is rotation axis -->
			<inertia ixx="24140e-6" ixy="0" ixz="0" iyy="15166e-6" iyz="0" izz="15166e-6" />   
		</inertial>
	</link>
	<joint name="wheel_urdf_4_UCS1_to_wheel_urdf_4_Base" type="fixed">
		<parent link="wheel_urdf_4_UCS1" />
		<child link="wheel_urdf_4_Base" />
		<origin rpy="-0.0 1.5707963057214722 0.0" xyz="-0.00048 0.00039 0.07671" />
	</joint>
	<link name="bigbot_UCSRR">
		<inertial>
			<mass value="2e-06" />
			<inertia ixx="1.1e-09" ixy="0" ixz="0" iyy="1.1e-09" iyz="0" izz="1.1e-09" />
		</inertial>
	</link>
	<joint name="bigbot_Base_to_bigbot_UCSRR" type="fixed">
		<parent link="bigbot_Base" />
		<child link="bigbot_UCSRR" />
		<origin rpy="1.5707963267948966 0.0 0.0" xyz="-0.27753 -0.16887 0.17107" />
	</joint>
	<joint name="bigbot_UCSRR_to_wheel_urdf_2_UCS1" type="continuous">
		<parent link="bigbot_UCSRR" />
		<child link="wheel_urdf_2_UCS1" />
		<origin rpy="0.0 0.0 0.0" xyz="0.00000 0.00000 0.00000" />
		<axis xyz="0 0 1" />
	</joint>
	<link name="wheel_urdf_2_UCS1">
		<inertial>
			<mass value="2e-06" />
			<inertia ixx="1.1e-09" ixy="0" ixz="0" iyy="1.1e-09" iyz="0" izz="1.1e-09" />
		</inertial>
	</link>
	<link name="wheel_urdf_2_Base">
		<visual>
			<origin rpy="0 0 0" xyz="0.00000 0.00000 0.00000" />
			<geometry>
				<mesh filename="package://bigbot_description/models/bigbot/meshes/wheel.dae" scale="0.001 0.001 0.001" />
			</geometry>
		</visual>
		<inertial>
			<origin xyz="0.00016 -0.00000 0.00000" />
			<mass value="2.63" /><!-- x is rotation axis -->
			<inertia ixx="24140e-6" ixy="0" ixz="0" iyy="15166e-6" iyz="0" izz="15166e-6" />
    		</inertial>
	</link>
	<joint name="wheel_urdf_2_UCS1_to_wheel_urdf_2_Base" type="fixed">
		<parent link="wheel_urdf_2_UCS1" />
		<child link="wheel_urdf_2_Base" />
		<origin rpy="-0.0 1.5707963057214722 0.0" xyz="-0.00048 0.00039 0.07671" />
	</joint>
	<link name="bigbot_UCSTF">
		<inertial>
			<mass value="2e-06" />
			<inertia ixx="1.1e-09" ixy="0" ixz="0" iyy="1.1e-09" iyz="0" izz="1.1e-09" />
		</inertial>
	</link>
	<joint name="bigbot_Base_to_bigbot_UCSTF" type="fixed">
		<parent link="bigbot_Base" />
		<child link="bigbot_UCSTF" />
		<origin rpy="0.0 0.0 0.0" xyz="0.37500 0.00000 0.48000" />
	</joint>
	<joint name="bigbot_UCSTF_to_Assembly_fixposition_frame_1_UCS1" type="fixed">
		<parent link="bigbot_UCSTF" />
		<child link="Assembly_fixposition_frame_1_UCS1" />
		<origin rpy="0.0 0.0 0.0" xyz="0.00000 0.00000 0.00000" />
	</joint>
	<link name="Assembly_fixposition_frame_1_UCS1">
		<inertial>
			<mass value="2e-06" />
			<inertia ixx="1.1e-09" ixy="0" ixz="0" iyy="1.1e-09" iyz="0" izz="1.1e-09" />
		</inertial>
	</link>
	<link name="Assembly_fixposition_frame_1_Base">
		<visual>
			<origin rpy="0 0 0" xyz="0.00000 0.00000 0.00000" />
			<geometry>
				<mesh filename="package://bigbot_description/models/bigbot/meshes/fixpos.dae" scale="0.001 0.001 0.001" />
			</geometry>
		</visual>
		<inertial>
			<origin xyz="-0.00000 0.00048 0.00008" />
			<mass value="1.5" />
			<inertia ixx="1174e-6" ixy="1e-6" ixz="-1.199e-6" iyy="15542e-6" iyz="-105e-6" izz="15095e-6" />
		</inertial>
	</link>
	<joint name="Assembly_fixposition_frame_1_UCS1_to_Assembly_fixposition_frame_1_Base" type="fixed">
		<parent link="Assembly_fixposition_frame_1_UCS1" />
		<child link="Assembly_fixposition_frame_1_Base" />
		<origin rpy="1.5707963267948966 0.0 1.5707963267948966" xyz="-0.06000 0.00000 0.00000" />
	</joint>
	<link name="Assembly_fixposition_frame_1_UCSCAMERA">
		<inertial>
			<mass value="2e-06" />
			<inertia ixx="1.1e-09" ixy="0" ixz="0" iyy="1.1e-09" iyz="0" izz="1.1e-09" />
		</inertial>
	</link>
	<joint name="Assembly_fixposition_frame_1_Base_to_Assembly_fixposition_frame_1_UCSCAMERA" type="fixed">
		<parent link="Assembly_fixposition_frame_1_Base" />
		<child link="Assembly_fixposition_frame_1_UCSCAMERA" />
		<origin rpy="-1.5707963267948966 -1.5707963267948966 0.0" xyz="0.00000 0.04900 0.07373" />
	</joint>
	<link name="Assembly_fixposition_frame_1_UCSGPS">
		<inertial>
			<mass value="2e-06" />
			<inertia ixx="1.1e-09" ixy="0" ixz="0" iyy="1.1e-09" iyz="0" izz="1.1e-09" />
		</inertial>
	</link>
	<joint name="Assembly_fixposition_frame_1_Base_to_Assembly_fixposition_frame_1_UCSGPS" type="fixed">
		<parent link="Assembly_fixposition_frame_1_Base" />
		<child link="Assembly_fixposition_frame_1_UCSGPS" />
		<origin rpy="-1.5707963267948966 -1.5707963267948966 0.0" xyz="0.00000 0.06300 0.03012" />
	</joint>
	<link name="bigbot_UCSTR">
		<inertial>
			<mass value="2e-06" />
			<inertia ixx="1.1e-09" ixy="0" ixz="0" iyy="1.1e-09" iyz="0" izz="1.1e-09" />
		</inertial>
	</link>
	<joint name="bigbot_Base_to_bigbot_UCSTR" type="fixed">
		<parent link="bigbot_Base" />
		<child link="bigbot_UCSTR" />
		<origin rpy="0.0 0.0 0.0" xyz="-0.37500 0.00000 0.48000" />
	</joint>
	<link name="bigbot_UCSBarF">
		<inertial>
			<mass value="2e-06" />
			<inertia ixx="1.1e-09" ixy="0" ixz="0" iyy="1.1e-09" iyz="0" izz="1.1e-09" />
		</inertial>
	</link>
	<joint name="bigbot_Base_to_bigbot_UCSBarF" type="fixed">
		<parent link="bigbot_Base" />
		<child link="bigbot_UCSBarF" />
		<origin rpy="0.0 0.0 0.0" xyz="0.44600 0.00000 0.30600" />
	</joint>
	<joint name="bigbot_UCSBarF_to_Assembly_TIM_lidar_urdf_1_UCS1" type="fixed">
		<parent link="bigbot_UCSBarF" />
		<child link="Assembly_TIM_lidar_urdf_1_UCS1" />
		<origin rpy="0.0 0.0 0.0" xyz="0.00000 0.00000 0.00000" />
	</joint>
	<link name="Assembly_TIM_lidar_urdf_1_UCS1">
		<inertial>
			<mass value="2e-06" />
			<inertia ixx="1.1e-09" ixy="0" ixz="0" iyy="1.1e-09" iyz="0" izz="1.1e-09" />
		</inertial>
	</link>
	<link name="Assembly_TIM_lidar_urdf_1_Base">
		<visual>
			<origin rpy="0 0 0" xyz="0.00000 0.00000 0.00000" />
			<geometry>
				<mesh filename="package://bigbot_description/models/bigbot/meshes/tim_lidar.dae" scale="0.01 0.01 0.01" />
			</geometry>
		</visual>
		<inertial>
			<origin xyz="-0.00000 0.00002 0.00042" />
			<mass value="0.41" />
			<inertia ixx="375.5e-6" ixy="58.4e-8" ixz="-0.068E-6" iyy="521.7E-6" iyz="1.547E-6" izz="323.259E-6" />
		</inertial>
	</link>
	<joint name="Assembly_TIM_lidar_urdf_1_UCS1_to_Assembly_TIM_lidar_urdf_1_Base" type="fixed">
		<parent link="Assembly_TIM_lidar_urdf_1_UCS1" />
		<child link="Assembly_TIM_lidar_urdf_1_Base" />
		<origin rpy="0.0 0.0 1.5707963267948966" xyz="0.00000 0.00000 0.00000" />
	</joint>
	<link name="Assembly_TIM_lidar_urdf_1_UCS2">
		<inertial>
			<mass value="2e-06" />
			<inertia ixx="1.1e-09" ixy="0" ixz="0" iyy="1.1e-09" iyz="0" izz="1.1e-09" />
		</inertial>
	</link>
	<joint name="Assembly_TIM_lidar_urdf_1_Base_to_Assembly_TIM_lidar_urdf_1_UCS2" type="fixed">
		<parent link="Assembly_TIM_lidar_urdf_1_Base" />
		<child link="Assembly_TIM_lidar_urdf_1_UCS2" />
		<origin rpy="0.0 0.0 -1.5707963267948966" xyz="0.00000 0.00000 0.08500" />
	</joint>
	<link name="bigbot_UCSBarR">
		<inertial>
			<mass value="2e-06" />
			<inertia ixx="1.1e-09" ixy="0" ixz="0" iyy="1.1e-09" iyz="0" izz="1.1e-09" />
		</inertial>
	</link>
	<joint name="bigbot_Base_to_bigbot_UCSBarR" type="fixed">
		<parent link="bigbot_Base" />
		<child link="bigbot_UCSBarR" />
		<origin rpy="0.0 0.0 0.0" xyz="-0.44600 0.00000 0.30600" />
	</joint>
</robot>
