<?xml version="1.0" ?>
<sdf version='1.7'>
  <model name='Bigbot'>
    <link name='base_link'>
      <inertial>
        <pose>0.005541 -3e-05 0.010091 0 -0 0</pose>
        <mass>118.71</mass>
        <inertia>
          <ixx>4.57012</ixx>
          <ixy>0.0300499</ixy>
          <ixz>-0.305381</ixz>
          <iyy>8.64363</iyy>
          <iyz>0.0340201</iyz>
          <izz>9.83233</izz>
        </inertia>
      </inertial>
      <collision name='base_link_fixed_joint_lump__bigbot_Base_collision'>
        <pose>0 0 0.32 0 -0 0</pose>
        <geometry>
          <box>
            <size>0.42 0.36 0.32</size>
          </box>
        </geometry>
      </collision>
      <visual name='base_link_fixed_joint_lump__bigbot_Base_visual'>
        <pose>0 0 0 0 -0 0</pose>
        <geometry>
          <mesh>
            <scale>0.001 0.001 0.001</scale>
            <uri>model://bigbot/meshes/bigbot_frame.dae</uri>
          </mesh>
        </geometry>
      </visual>
      <visual name='base_link_fixed_joint_lump__Assembly_TIM_lidar_urdf_1_Base_visual_1'>
        <pose>0.446 0 0.306 0 -0 1.5708</pose>
        <geometry>
          <mesh>
            <scale>0.01 0.01 0.01</scale>
            <uri>model://bigbot/meshes/tim_lidar.dae</uri>
          </mesh>
        </geometry>
      </visual>
      <visual name='base_link_fixed_joint_lump__Assembly_fixposition_frame_1_Base_visual_2'>
        <pose>0.315 0 0.48 1.5708 -0 1.5708</pose>
        <geometry>
          <mesh>
            <scale>0.001 0.001 0.001</scale>
            <uri>model://bigbot/meshes/fixpos.dae</uri>
          </mesh>
        </geometry>
      </visual>
      <sensor name='lidar_front' type='ray'>
        <always_on>1</always_on>
        <visualize>1</visualize>
        <update_rate>5</update_rate>
        <ray>
          <scan>
            <horizontal>
              <samples>360</samples>
              <resolution>1</resolution>
              <min_angle>-2</min_angle>
              <max_angle>2</max_angle>
            </horizontal>
          </scan>
          <range>
            <min>0.1</min>
            <max>5</max>
            <resolution>0.015</resolution>
          </range>
          <noise>
            <type>gaussian</type>
            <mean>0</mean>
            <stddev>0.01</stddev>
          </noise>
        </ray>
        <plugin name='bigbot_laserscan' filename='libgazebo_ros_ray_sensor.so'>
          <ros>
            <remapping>~/out:=scan</remapping>
          </ros>
          <output_type>sensor_msgs/LaserScan</output_type>
          <frame_name>base_scan</frame_name>
        </plugin>
        <pose>0.446 0 0.391 0 -0 0</pose>
      </sensor>
      <sensor name='my_gps' type='gps'>
        <always_on>1</always_on>
        <update_rate>30</update_rate>
        <plugin name='gps_plugin' filename='libgazebo_ros_gps_sensor.so'>
          <ros>
            <namespace/>
            <remapping>~/out:=gps/fix_base</remapping>
          </ros>
        </plugin>
        <pose>0.34512 -0 0.543 0 -0 -0</pose>
      </sensor>
    </link>
    <joint name='bigbot_UCSLF_to_wheel_urdf_3_UCS1' type='revolute'>
      <pose relative_to='base_link'>0.27753 0.16887 0.17107 -1.5708 0 0</pose>
      <parent>base_link</parent>
      <child>wheel_urdf_3_UCS1</child>
      <axis>
        <xyz>0 0 1</xyz>
        <limit>
          <lower>-1e+16</lower>
          <upper>1e+16</upper>
        </limit>
        <dynamics>
          <spring_reference>0</spring_reference>
          <spring_stiffness>0</spring_stiffness>
        </dynamics>
      </axis>
    </joint>
    <link name='wheel_urdf_3_UCS1'>
      <pose relative_to='bigbot_UCSLF_to_wheel_urdf_3_UCS1'>0 0 0 0 -0 0</pose>
      <inertial>
        <pose>-0.00048 0.00039 0.07655 0 -0 0</pose>
        <mass>2.63</mass>
        <inertia>
          <ixx>0.015166</ixx>
          <ixy>3.744e-13</ixy>
          <ixz>7.34879e-11</ixz>
          <iyy>0.015166</iyy>
          <iyz>-5.9709e-11</iyz>
          <izz>0.02414</izz>
        </inertia>
      </inertial>
      <collision name='wheel_urdf_3_UCS1_fixed_joint_lump__wheel_urdf_3_Base_collision'>
        <pose>-0.00048 0.00039 0.05671 3.14159 0.000796 3.14159</pose>
        <geometry>
          <cylinder>
            <length>0.135</length>
            <radius>0.16</radius>
          </cylinder>
        </geometry>
        <surface>
          <contact>
            <ode>
              <kp>1e+07</kp>
              <kd>1</kd>
            </ode>
          </contact>
          <friction>
            <ode>
              <mu>1</mu>
              <mu2>0.5</mu2>
              <fdir1>1 0 0</fdir1>
            </ode>
          </friction>
        </surface>
      </collision>
      <visual name='wheel_urdf_3_UCS1_fixed_joint_lump__wheel_urdf_3_Base_visual'>
        <pose>-0.00048 0.00039 0.07671 0 1.5708 0</pose>
        <geometry>
          <mesh>
            <scale>0.001 0.001 0.001</scale>
            <uri>model://bigbot/meshes/wheel.dae</uri>
          </mesh>
        </geometry>
      </visual>
    </link>
    <joint name='bigbot_UCSLR_to_wheel_urdf_4_UCS1' type='revolute'>
      <pose relative_to='base_link'>-0.27753 0.16887 0.17107 -1.5708 0 0</pose>
      <parent>base_link</parent>
      <child>wheel_urdf_4_UCS1</child>
      <axis>
        <xyz>0 0 1</xyz>
        <limit>
          <lower>-1e+16</lower>
          <upper>1e+16</upper>
        </limit>
        <dynamics>
          <spring_reference>0</spring_reference>
          <spring_stiffness>0</spring_stiffness>
        </dynamics>
      </axis>
    </joint>
    <link name='wheel_urdf_4_UCS1'>
      <pose relative_to='bigbot_UCSLR_to_wheel_urdf_4_UCS1'>0 0 0 0 -0 0</pose>
      <inertial>
        <pose>-0.00048 0.00039 0.07655 0 -0 0</pose>
        <mass>2.63</mass>
        <inertia>
          <ixx>0.015166</ixx>
          <ixy>3.744e-13</ixy>
          <ixz>7.34879e-11</ixz>
          <iyy>0.015166</iyy>
          <iyz>-5.9709e-11</iyz>
          <izz>0.02414</izz>
        </inertia>
      </inertial>
      <collision name='wheel_urdf_4_UCS1_fixed_joint_lump__wheel_urdf_4_Base_collision'>
        <pose>-0.00048 0.00039 0.05671 3.14159 0.000796 3.14159</pose>
        <geometry>
          <cylinder>
            <length>0.135</length>
            <radius>0.16</radius>
          </cylinder>
        </geometry>
        <surface>
          <contact>
            <ode>
              <kp>1e+07</kp>
              <kd>1</kd>
            </ode>
          </contact>
          <friction>
            <ode>
              <mu>1</mu>
              <mu2>0.5</mu2>
              <fdir1>1 0 0</fdir1>
            </ode>
          </friction>
        </surface>
      </collision>
      <visual name='wheel_urdf_4_UCS1_fixed_joint_lump__wheel_urdf_4_Base_visual'>
        <pose>-0.00048 0.00039 0.07671 0 1.5708 0</pose>
        <geometry>
          <mesh>
            <scale>0.001 0.001 0.001</scale>
            <uri>model://bigbot/meshes/wheel.dae</uri>
          </mesh>
        </geometry>
      </visual>
    </link>
    <joint name='bigbot_UCSRF_to_wheel_urdf_1_UCS1' type='revolute'>
      <pose relative_to='base_link'>0.27753 -0.16887 0.17107 1.5708 -0 0</pose>
      <parent>base_link</parent>
      <child>wheel_urdf_1_UCS1</child>
      <axis>
        <xyz>0 0 1</xyz>
        <limit>
          <lower>-1e+16</lower>
          <upper>1e+16</upper>
        </limit>
        <dynamics>
          <spring_reference>0</spring_reference>
          <spring_stiffness>0</spring_stiffness>
        </dynamics>
      </axis>
    </joint>
    <link name='wheel_urdf_1_UCS1'>
      <pose relative_to='bigbot_UCSRF_to_wheel_urdf_1_UCS1'>0 0 0 0 -0 0</pose>
      <inertial>
        <pose>-0.00048 0.00039 0.07655 0 -0 0</pose>
        <mass>2.63</mass>
        <inertia>
          <ixx>0.015166</ixx>
          <ixy>3.744e-13</ixy>
          <ixz>7.34879e-11</ixz>
          <iyy>0.015166</iyy>
          <iyz>-5.9709e-11</iyz>
          <izz>0.02414</izz>
        </inertia>
      </inertial>
      <collision name='wheel_urdf_1_UCS1_fixed_joint_lump__wheel_urdf_1_Base_collision'>
        <pose>-0.00048 0.00039 0.05671 3.14159 0.000796 3.14159</pose>
        <geometry>
          <cylinder>
            <length>0.135</length>
            <radius>0.16</radius>
          </cylinder>
        </geometry>
        <surface>
          <contact>
            <ode>
              <kp>1e+07</kp>
              <kd>1</kd>
            </ode>
          </contact>
          <friction>
            <ode>
              <mu>1</mu>
              <mu2>0.5</mu2>
              <fdir1>1 0 0</fdir1>
            </ode>
          </friction>
        </surface>
      </collision>
      <visual name='wheel_urdf_1_UCS1_fixed_joint_lump__wheel_urdf_1_Base_visual'>
        <pose>-0.00048 0.00039 0.07671 0 1.5708 0</pose>
        <geometry>
          <mesh>
            <scale>0.001 0.001 0.001</scale>
            <uri>model://bigbot/meshes/wheel.dae</uri>
          </mesh>
        </geometry>
      </visual>
    </link>
    <joint name='bigbot_UCSRR_to_wheel_urdf_2_UCS1' type='revolute'>
      <pose relative_to='base_link'>-0.27753 -0.16887 0.17107 1.5708 -0 0</pose>
      <parent>base_link</parent>
      <child>wheel_urdf_2_UCS1</child>
      <axis>
        <xyz>0 0 1</xyz>
        <limit>
          <lower>-1e+16</lower>
          <upper>1e+16</upper>
        </limit>
        <dynamics>
          <spring_reference>0</spring_reference>
          <spring_stiffness>0</spring_stiffness>
        </dynamics>
      </axis>
    </joint>
    <link name='wheel_urdf_2_UCS1'>
      <pose relative_to='bigbot_UCSRR_to_wheel_urdf_2_UCS1'>0 0 0 0 -0 0</pose>
      <inertial>
        <pose>-0.00048 0.00039 0.07655 0 -0 0</pose>
        <mass>2.63</mass>
        <inertia>
          <ixx>0.015166</ixx>
          <ixy>3.744e-13</ixy>
          <ixz>7.34879e-11</ixz>
          <iyy>0.015166</iyy>
          <iyz>-5.9709e-11</iyz>
          <izz>0.02414</izz>
        </inertia>
      </inertial>
      <collision name='wheel_urdf_2_UCS1_fixed_joint_lump__wheel_urdf_2_Base_collision'>
        <pose>-0.00048 0.00039 0.05671 3.14159 0.000796 3.14159</pose>
        <geometry>
          <cylinder>
            <length>0.135</length>
            <radius>0.16</radius>
          </cylinder>
        </geometry>
        <surface>
          <contact>
            <ode>
              <kp>1e+07</kp>
              <kd>1</kd>
            </ode>
          </contact>
          <friction>
            <ode>
              <mu>1</mu>
              <mu2>0.5</mu2>
              <fdir1>1 0 0</fdir1>
            </ode>
          </friction>
        </surface>
      </collision>
      <visual name='wheel_urdf_2_UCS1_fixed_joint_lump__wheel_urdf_2_Base_visual'>
        <pose>-0.00048 0.00039 0.07671 0 1.5708 0</pose>
        <geometry>
          <mesh>
            <scale>0.001 0.001 0.001</scale>
            <uri>model://bigbot/meshes/wheel.dae</uri>
          </mesh>
        </geometry>
      </visual>
    </link>
    <static>0</static>
    <plugin name='gazebo_ros2_control' filename='libgazebo_ros2_control.so'>
      <robot_param>robot_description</robot_param>
      <robot_namespace/>
      <robot_param_node>robot_state_publisher</robot_param_node>
      <parameters><!-- your bigbot_control path to bigbot_control/config/control.yaml --></parameters>
    </plugin>
  </model>
</sdf>
